2019-06-23 20:35:20,918 ERROR: Exception on / [POST] [in c:\users\tmais\envs\hello_flask\lib\site-packages\flask\app.py:1761]
Traceback (most recent call last):
  File "c:\users\tmais\envs\hello_flask\lib\site-packages\urllib3\connection.py", line 159, in _new_conn
    (self._dns_host, self.port), self.timeout, **extra_kw)
  File "c:\users\tmais\envs\hello_flask\lib\site-packages\urllib3\util\connection.py", line 80, in create_connection
    raise err
  File "c:\users\tmais\envs\hello_flask\lib\site-packages\urllib3\util\connection.py", line 70, in create_connection
    sock.connect(sa)
ConnectionRefusedError: [WinError 10061] No connection could be made because the target machine actively refused it

During handling of the above exception, another exception occurred:

Traceback (most recent call last):
  File "c:\users\tmais\envs\hello_flask\lib\site-packages\elasticsearch\connection\http_urllib3.py", line 232, in perform_request
    method, url, body, retries=Retry(False), headers=request_headers, **kw
  File "c:\users\tmais\envs\hello_flask\lib\site-packages\urllib3\connectionpool.py", line 638, in urlopen
    _stacktrace=sys.exc_info()[2])
  File "c:\users\tmais\envs\hello_flask\lib\site-packages\urllib3\util\retry.py", line 343, in increment
    raise six.reraise(type(error), error, _stacktrace)
  File "c:\users\tmais\envs\hello_flask\lib\site-packages\urllib3\packages\six.py", line 686, in reraise
    raise value
  File "c:\users\tmais\envs\hello_flask\lib\site-packages\urllib3\connectionpool.py", line 600, in urlopen
    chunked=chunked)
  File "c:\users\tmais\envs\hello_flask\lib\site-packages\urllib3\connectionpool.py", line 354, in _make_request
    conn.request(method, url, **httplib_request_kw)
  File "c:\program files (x86)\python36-32\Lib\http\client.py", line 1239, in request
    self._send_request(method, url, body, headers, encode_chunked)
  File "c:\program files (x86)\python36-32\Lib\http\client.py", line 1285, in _send_request
    self.endheaders(body, encode_chunked=encode_chunked)
  File "c:\program files (x86)\python36-32\Lib\http\client.py", line 1234, in endheaders
    self._send_output(message_body, encode_chunked=encode_chunked)
  File "c:\program files (x86)\python36-32\Lib\http\client.py", line 1026, in _send_output
    self.send(msg)
  File "c:\program files (x86)\python36-32\Lib\http\client.py", line 964, in send
    self.connect()
  File "c:\users\tmais\envs\hello_flask\lib\site-packages\urllib3\connection.py", line 181, in connect
    conn = self._new_conn()
  File "c:\users\tmais\envs\hello_flask\lib\site-packages\urllib3\connection.py", line 168, in _new_conn
    self, "Failed to establish a new connection: %s" % e)
urllib3.exceptions.NewConnectionError: <urllib3.connection.HTTPConnection object at 0x04A674D0>: Failed to establish a new connection: [WinError 10061] No connection could be made because the target machine actively refused it

During handling of the above exception, another exception occurred:

Traceback (most recent call last):
  File "c:\users\tmais\envs\hello_flask\lib\site-packages\flask\app.py", line 2292, in wsgi_app
    response = self.full_dispatch_request()
  File "c:\users\tmais\envs\hello_flask\lib\site-packages\flask\app.py", line 1815, in full_dispatch_request
    rv = self.handle_user_exception(e)
  File "c:\users\tmais\envs\hello_flask\lib\site-packages\flask\app.py", line 1718, in handle_user_exception
    reraise(exc_type, exc_value, tb)
  File "c:\users\tmais\envs\hello_flask\lib\site-packages\flask\_compat.py", line 35, in reraise
    raise value
  File "c:\users\tmais\envs\hello_flask\lib\site-packages\flask\app.py", line 1813, in full_dispatch_request
    rv = self.dispatch_request()
  File "c:\users\tmais\envs\hello_flask\lib\site-packages\flask\app.py", line 1799, in dispatch_request
    return self.view_functions[rule.endpoint](**req.view_args)
  File "c:\users\tmais\envs\hello_flask\lib\site-packages\flask_login\utils.py", line 261, in decorated_view
    return func(*args, **kwargs)
  File "C:\Users\tmais\Documents\Coding\Python\Projects\hello_flask\app\main\routes.py", line 35, in index
    db.session.commit()
  File "c:\users\tmais\envs\hello_flask\lib\site-packages\sqlalchemy\orm\scoping.py", line 153, in do
    return getattr(self.registry(), name)(*args, **kwargs)
  File "c:\users\tmais\envs\hello_flask\lib\site-packages\sqlalchemy\orm\session.py", line 943, in commit
    self.transaction.commit()
  File "c:\users\tmais\envs\hello_flask\lib\site-packages\sqlalchemy\orm\session.py", line 474, in commit
    self.session.dispatch.after_commit(self.session)
  File "c:\users\tmais\envs\hello_flask\lib\site-packages\sqlalchemy\event\attr.py", line 246, in __call__
    fn(*args, **kw)
  File "C:\Users\tmais\Documents\Coding\Python\Projects\hello_flask\app\models.py", line 37, in after_commit
    add_to_index(obj.__tablename__, obj)
  File "C:\Users\tmais\Documents\Coding\Python\Projects\hello_flask\app\search.py", line 11, in add_to_index
    body=payload)
  File "c:\users\tmais\envs\hello_flask\lib\site-packages\elasticsearch\client\utils.py", line 84, in _wrapped
    return func(*args, params=params, **kwargs)
  File "c:\users\tmais\envs\hello_flask\lib\site-packages\elasticsearch\client\__init__.py", line 364, in index
    "POST", _make_path(index, doc_type, id), params=params, body=body
  File "c:\users\tmais\envs\hello_flask\lib\site-packages\elasticsearch\transport.py", line 353, in perform_request
    timeout=timeout,
  File "c:\users\tmais\envs\hello_flask\lib\site-packages\elasticsearch\connection\http_urllib3.py", line 244, in perform_request
    raise ConnectionError("N/A", str(e), e)
elasticsearch.exceptions.ConnectionError: ConnectionError(<urllib3.connection.HTTPConnection object at 0x04A674D0>: Failed to establish a new connection: [WinError 10061] No connection could be made because the target machine actively refused it) caused by: NewConnectionError(<urllib3.connection.HTTPConnection object at 0x04A674D0>: Failed to establish a new connection: [WinError 10061] No connection could be made because the target machine actively refused it)
2019-06-23 20:48:16,559 INFO: Microblog startup [in C:\Users\tmais\Documents\Coding\Python\Projects\hello_flask\app\__init__.py:77]
2019-06-23 21:06:38,932 INFO: Microblog startup [in C:\Users\tmais\Documents\Coding\Python\Projects\hello_flask\app\__init__.py:77]
2019-06-23 21:14:28,439 INFO: Microblog startup [in C:\Users\tmais\Documents\Coding\Python\Projects\hello_flask\app\__init__.py:77]
2019-06-23 21:15:56,878 INFO: Microblog startup [in C:\Users\tmais\Documents\Coding\Python\Projects\hello_flask\app\__init__.py:77]
2019-06-23 21:28:22,977 INFO: Microblog startup [in C:\Users\tmais\Documents\Coding\Python\Projects\hello_flask\app\__init__.py:77]
2019-06-23 21:30:24,195 INFO: Microblog startup [in C:\Users\tmais\Documents\Coding\Python\Projects\hello_flask\app\__init__.py:77]
